Workbook

Sheet 입출고대장
A1: 입출고대장
A2: 날짜 | B2: 구분 | C2: 원산지 | D2: *와인명 | E2: 빈티지 | F2: 보관위치 | G2: 수량 | H2: 사용처/인수자 | I2: 비고
A3: 46265 | B3: 입고 | C3: 미국 | D3: 로버트 몬다비,까베르네 소비뇽 리저브 | E3: 2009 | F3: 1번랙 | G3: 3 | H3: 초기재고
A4: 46265 | B4: 입고 | C4: 미국 | D4: 로버트 몬다비,까베르네 소비뇽 리저브 | E4: 2010 | F4: 1번랙 | G4: 3 | H4: 초기재고
A5: 46265 | B5: 입고 | C5: 미국 | D5: 로버트 몬다비,까베르네 소비뇽 리저브 | E5: 2011 | F5: 1번랙 | G5: 3 | H5: 초기재고
A6: 46265 | B6: 입고 | C6: 미국 | D6: 로버트 몬다비,까베르네 소비뇽 리저브 | E6: 2012 | F6: 1번랙 | G6: 3 | H6: 초기재고
A7: 46265 | B7: 입고 | C7: 미국 | D7: 로버트 몬다비,까베르네 소비뇽 리저브 | E7: 2010 | F7: 1번랙 | G7: 9 | H7: 초기재고
A8: 46265 | B8: 입고 | C8: 호주 | D8: 토브렉, 런릭 | E8: 2007 | F8: 1번랙 | G8: 6 | H8: 초기재고
A9: 46265 | B9: 입고 | C9: 호주 | D9: 토브렉, 런릭 | E9: 2006 | F9: 1번랙 | G9: 1 | H9: 초기재고
A10: 46265 | B10: 입고 | C10: 호주 | D10: 토브렉, 런릭 | E10: 2007 | F10: 1번랙 | G10: 5 | H10: 초기재고
A11: 46265 | B11: 입고 | C11: 호주 | D11: 토브렉, 레어드 1500ml | E11: 2005 | F11: 1번랙 | G11: 2 | H11: 초기재고 | I11: 매그넘
A12: 46265 | B12: 입고 | C12: 미국 | D12: 로버트 몬다비,까베르네 소비뇽 버티칼 세트 | E12: NV | F12: 2번랙 | G12: 3 | H12: 초기재고 | I12: 세트상품
A13: 46265 | B13: 입고 | C13: 미국 | D13: 로버트 몬다비,까베르네 소비뇽 리저브(50주년 에디션) | E13: 2013 | F13: 2번랙 | G13: 3 | H13: 초기재고 | I13: 50주년 에디션
A14: 46265 | B14: 입고 | C14: 프랑스 | D14: 페블레, 꼬르똥 샤를마뉴 그랑 크뤼 | E14: 2010 | F14: 2번랙 | G14: 12 | H14: 초기재고
A15: 46265 | B15: 입고 | C15: 프랑스 | D15: 페블레,비엥브뉘 바타르 몽라쉐 그랑 크뤼 | E15: 2011 | F15: 3번랙 | G15: 6 | H15: 초기재고 | I15: 검정 나무 케이스 6병
A16: 46265 | B16: 입고 | C16: 프랑스 | D16: 페블레,바타르 몽라쉐 그랑 크뤼 | E16: 2010 | F16: 3번랙 | G16: 3 | H16: 초기재고
A17: 46265 | B17: 입고 | C17: 프랑스 | D17: 페블레,바타르 몽라쉐 그랑 크뤼 | E17: 2021 | F17: 3번랙 | G17: 3 | H17: 초기재고
A18: 46265 | B18: 입고 | C18: 프랑스 | D18: 페블레, 샹베르땡 끌로 드 베즈 우브레 로딘 그랑크뤼 | E18: 2018 | F18: 3번랙 | G18: 4 | H18: 초기재고
A19: 46265 | B19: 입고 | C19: 프랑스 | D19: 페블레, 샹베르땡 끌로 드 베즈 우브레 로딘 그랑크뤼 | E19: 2020 | F19: 3번랙 | G19: 2 | H19: 초기재고
A20: 46265 | B20: 입고 | C20: 프랑스 | D20: 페블레, 샹베르땡 끌로 드 베즈 우브레 로딘 그랑크뤼 | E20: 2019 | F20: 3번랙 | G20: 6 | H20: 초기재고
A21: 46265 | B21: 입고 | C21: 이탈리아 | D21: 루체 브루넬로 디 몬탈치노 1500ml | E21: 2012 | F21: 4번랙 | G21: 4 | H21: 초기재고 | I21: 매그넘
A22: 46265 | B22: 입고 | C22: 이탈리아 | D22: 루체 브루넬로 디 몬탈치노 1500ml | E22: 2009 | F22: 4번랙 | G22: 4 | H22: 초기재고 | I22: 매그넘
A23: 46265 | B23: 입고 | C23: 이탈리아 | D23: 루체 브루넬로 디 몬탈치노 3000ml | E23: 2012 | F23: 4번랙 | G23: 2 | H23: 초기재고 | I23: 더블매그넘
A24: 46265 | B24: 입고 | C24: 이탈리아 | D24: 프레스코발디,카스텔지오콘도 리제르바 1500ml | E24: 2008 | F24: 4번랙 | G24: 3 | H24: 초기재고 | I24: 매그넘
A25: 46265 | B25: 입고 | C25: 이탈리아 | D25: 프레스코발디,카스텔지오콘도 리제르바 1500ml | E25: 2010 | F25: 4번랙 | G25: 7 | H25: 초기재고 | I25: 매그넘
A26: 46265 | B26: 입고 | C26: 이탈리아 | D26: 프레스코발디,카스텔지오콘도 리제르바 3000ml | E26: 2010 | F26: 4번랙 | G26: 2 | H26: 초기재고 | I26: 더블매그넘
A27: 46265 | B27: 입고 | C27: 프랑스 | D27: 아르망드 브리냑 로제 750ml | E27: NV | F27: 5번랙 | G27: 6 | H27: 초기재고 | I27: 샴페인
A28: 46265 | B28: 입고 | C28: 프랑스 | D28: 헨리옷 HENRIOT 샴페인 | E28: 1996 | F28: 5번랙 | G28: 4 | H28: 초기재고 | I28: 샴페인
A29: 46265 | B29: 입고 | C29: 프랑스 | D29: 크룩 KRUG 샴페인 | E29: NV | F29: 5번랙 | G29: 6 | H29: 초기재고 | I29: 샴페인
A30: 46265 | B30: 입고 | C30: 미국 | D30: 로버트 몬다비 리저브 | E30: 2007 | F30: 5번랙 | G30: 1 | H30: 초기재고 | I30: 선물용
A31: 46265 | B31: 입고 | C31: 칠레 | D31: 비네도 차드윅 | E31: NV | F31: 5번랙 | G31: 1 | H31: 초기재고 | I31: 선물용
A32: 46265 | B32: 입고 | C32: 프랑스 | D32: 샤또 린치 바쥐 | E32: 2005 | F32: 5번랙 | G32: 1 | H32: 초기재고 | I32: 선물용
A33: 46265 | B33: 입고 | C33: 이탈리아 | D33: 루체 | E33: 2011 | F33: 5번랙 | G33: 1 | H33: 초기재고 | I33: 선물용
A34: 46265 | B34: 입고 | C34: 미국 | D34: 오퍼스원 | E34: 2010 | F34: 5번랙 | G34: 0 | H34: 초기재고 | I34: 선물용
A35: 46265 | B35: 입고 | C35: 호주 | D35: 우드커터스 쉬라즈 | E35: NV | F35: 5번랙 | G35: 1 | H35: 초기재고 | I35: 선물용
A36: 46265 | B36: 입고 | C36: 이탈리아 | D36: Masseto (T) | E36: 2014 | F36: 5번랙 | G36: 1 | H36: 초기재고
A37: 46265 | B37: 입고 | C37: 미국 | D37: Grgich Hills Yountville Old Vine C/S | E37: 2019 | F37: 5번랙 | G37: 2 | H37: 초기재고
A38: 46265 | B38: 입고 | C38: 프랑스 | D38: (OT)Domaine Coche-Dury Puligny Montrachet Les Enseigneres | E38: 2018 | F38: 5번랙 | G38: 1 | H38: 초기재고
A39: 46265 | B39: 입고 | C39: 프랑스 | D39: Phillip Pacalet Chambolle Musigny 1er Cru "Les Sentiers" | E39: 2021 | F39: 5번랙 | G39: 1 | H39: 초기재고
A40: 46265 | B40: 입고 | C40: 프랑스 | D40: (OT)Henri Boillot Chevalier Montrachet Grand Cru Blanc | E40: 2018 | F40: 5번랙 | G40: 1 | H40: 초기재고
...

Sheet 와인재고현황
A1: 와 인 재 고 현 황
A2: 원산지 | B2: 와인명 | C2: 빈티지 | D2: 보관위치 | E2: 총 입고량 | F2: 총 출고량 | G2: 현재고 | H2: 상태 | I2: 비고
A3: {=_xlfn.LET( _xlpm.data, _xlfn.UNIQUE(_xlfn._xlws.FILTER(입출고대장!C3:F2999, 입출고대장!D3:D2999<>"")), _xlpm.racks, INDEX(_xlpm.data,,4), _xlpm.rack_num, IFERROR(--_xlfn.TEXTBEFORE(_xlpm.racks, "번"), 999), _xlpm.country, INDEX(_xlpm.data,,1), _xlpm.w_name, INDEX(_xlpm.data,,2), _xlpm.vint, INDEX(_xlpm.data,,3), _xlfn.SORTBY(_xlpm.data, _xlpm.rack_num, 1, _xlpm.racks, 1, _xlpm.country, 1, _xlpm.w_name, 1, _xlpm.vint, 1) )} -> 미국 | B3: 로버트 몬다비,까베르네 소비뇽 리저브 | C3: 2009 | D3: 1번랙 | E3: {=_xlfn.MAP(INDEX(_xlfn.ANCHORARRAY(A3),,2), INDEX(_xlfn.ANCHORARRAY(A3),,3), INDEX(_xlfn.ANCHORARRAY(A3),,4), _xlfn.LAMBDA(_xlpm.w,_xlpm.v,_xlpm.l, SUMIFS(입출고대장!G:G, 입출고대장!D:D, _xlpm.w, 입출고대장!E:E, _xlpm.v, 입출고대장!F:F, _xlpm.l, 입출고대장!B:B, "입고")))} -> 3 | F3: {=_xlfn.MAP(INDEX(_xlfn.ANCHORARRAY(A3),,2), INDEX(_xlfn.ANCHORARRAY(A3),,3), INDEX(_xlfn.ANCHORARRAY(A3),,4), _xlfn.LAMBDA(_xlpm.w,_xlpm.v,_xlpm.l, SUMIFS(입출고대장!G:G, 입출고대장!D:D, _xlpm.w, 입출고대장!E:E, _xlpm.v, 입출고대장!F:F, _xlpm.l, 입출고대장!B:B, "출고")))} -> 0 | G3: {=_xlfn.ANCHORARRAY(E3) -_xlfn.ANCHORARRAY( F3)} -> 3 | H3: {=IF(_xlfn.ANCHORARRAY(G3)<=0, "재고없음", "정상")} -> 정상 | I3: {=IF(B3="", "", _xlfn.TEXTJOIN(", ", TRUE, _xlfn.UNIQUE(_xlfn._xlws.FILTER(입출고대장!$I:$I, (입출고대장!$D:$D=B3)*(입출고대장!$E:$E=C3)*(입출고대장!$F:$F=D3)*(입출고대장!$I:$I<>""), ""))))}
A4: 미국 | B4: 로버트 몬다비,까베르네 소비뇽 리저브 | C4: 2010 | D4: 1번랙 | E4: 12 | F4: 9 | G4: 3 | H4: 정상 | I4: {=IF(B4="", "", _xlfn.TEXTJOIN(", ", TRUE, _xlfn.UNIQUE(_xlfn._xlws.FILTER(입출고대장!$I:$I, (입출고대장!$D:$D=B4)*(입출고대장!$E:$E=C4)*(입출고대장!$F:$F=D4)*(입출고대장!$I:$I<>""), ""))))}
A5: 미국 | B5: 로버트 몬다비,까베르네 소비뇽 리저브 | C5: 2011 | D5: 1번랙 | E5: 3 | F5: 0 | G5: 3 | H5: 정상 | I5: {=IF(B5="", "", _xlfn.TEXTJOIN(", ", TRUE, _xlfn.UNIQUE(_xlfn._xlws.FILTER(입출고대장!$I:$I, (입출고대장!$D:$D=B5)*(입출고대장!$E:$E=C5)*(입출고대장!$F:$F=D5)*(입출고대장!$I:$I<>""), ""))))}
A6: 미국 | B6: 로버트 몬다비,까베르네 소비뇽 리저브 | C6: 2012 | D6: 1번랙 | E6: 3 | F6: 0 | G6: 3 | H6: 정상 | I6: {=IF(B6="", "", _xlfn.TEXTJOIN(", ", TRUE, _xlfn.UNIQUE(_xlfn._xlws.FILTER(입출고대장!$I:$I, (입출고대장!$D:$D=B6)*(입출고대장!$E:$E=C6)*(입출고대장!$F:$F=D6)*(입출고대장!$I:$I<>""), ""))))}
A7: 호주 | B7: 토브렉, 런릭 | C7: 2006 | D7: 1번랙 | E7: 1 | F7: 0 | G7: 1 | H7: 정상 | I7: {=IF(B7="", "", _xlfn.TEXTJOIN(", ", TRUE, _xlfn.UNIQUE(_xlfn._xlws.FILTER(입출고대장!$I:$I, (입출고대장!$D:$D=B7)*(입출고대장!$E:$E=C7)*(입출고대장!$F:$F=D7)*(입출고대장!$I:$I<>""), ""))))}
A8: 호주 | B8: 토브렉, 런릭 | C8: 2007 | D8: 1번랙 | E8: 11 | F8: 0 | G8: 11 | H8: 정상 | I8: {=IF(B8="", "", _xlfn.TEXTJOIN(", ", TRUE, _xlfn.UNIQUE(_xlfn._xlws.FILTER(입출고대장!$I:$I, (입출고대장!$D:$D=B8)*(입출고대장!$E:$E=C8)*(입출고대장!$F:$F=D8)*(입출고대장!$I:$I<>""), ""))))}
A9: 호주 | B9: 토브렉, 레어드 1500ml | C9: 2005 | D9: 1번랙 | E9: 2 | F9: 0 | G9: 2 | H9: 정상 | I9: {=IF(B9="", "", _xlfn.TEXTJOIN(", ", TRUE, _xlfn.UNIQUE(_xlfn._xlws.FILTER(입출고대장!$I:$I, (입출고대장!$D:$D=B9)*(입출고대장!$E:$E=C9)*(입출고대장!$F:$F=D9)*(입출고대장!$I:$I<>""), ""))))} -> 매그넘
A10: 미국 | B10: 더 마스코트 | C10: 2020 | D10: 1번랙(천장) | E10: 1 | F10: 0 | G10: 1 | H10: 정상 | I10: {=IF(B10="", "", _xlfn.TEXTJOIN(", ", TRUE, _xlfn.UNIQUE(_xlfn._xlws.FILTER(입출고대장!$I:$I, (입출고대장!$D:$D=B10)*(입출고대장!$E:$E=C10)*(입출고대장!$F:$F=D10)*(입출고대장!$I:$I<>""), ""))))}
A11: 미국 | B11: 씨네퀴넌 | C11: 2013 | D11: 1번랙(천장) | E11: 13 | F11: 0 | G11: 13 | H11: 정상 | I11: {=IF(B11="", "", _xlfn.TEXTJOIN(", ", TRUE, _xlfn.UNIQUE(_xlfn._xlws.FILTER(입출고대장!$I:$I, (입출고대장!$D:$D=B11)*(입출고대장!$E:$E=C11)*(입출고대장!$F:$F=D11)*(입출고대장!$I:$I<>""), ""))))}
A12: 미국 | B12: 제이드 팰리스 골프클럽 | C12: 2022 | D12: 1번랙(천장) | E12: 1 | F12: 0 | G12: 1 | H12: 정상 | I12: {=IF(B12="", "", _xlfn.TEXTJOIN(", ", TRUE, _xlfn.UNIQUE(_xlfn._xlws.FILTER(입출고대장!$I:$I, (입출고대장!$D:$D=B12)*(입출고대장!$E:$E=C12)*(입출고대장!$F:$F=D12)*(입출고대장!$I:$I<>""), ""))))}
A13: 미국 | B13: 피터 마이클, 레 파보 | C13: 2019 | D13: 1번랙(천장) | E13: 1 | F13: 0 | G13: 1 | H13: 정상 | I13: {=IF(B13="", "", _xlfn.TEXTJOIN(", ", TRUE, _xlfn.UNIQUE(_xlfn._xlws.FILTER(입출고대장!$I:$I, (입출고대장!$D:$D=B13)*(입출고대장!$E:$E=C13)*(입출고대장!$F:$F=D13)*(입출고대장!$I:$I<>""), ""))))}
A14: 스페인 | B14: 펠릭스 카예호, 셀렉시온 데 비녜도스 데 라 파밀리아 | C14: 2004 | D14: 1번랙(천장) | E14: 1 | F14: 0 | G14: 1 | H14: 정상 | I14: {=IF(B14="", "", _xlfn.TEXTJOIN(", ", TRUE, _xlfn.UNIQUE(_xlfn._xlws.FILTER(입출고대장!$I:$I, (입출고대장!$D:$D=B14)*(입출고대장!$E:$E=C14)*(입출고대장!$F:$F=D14)*(입출고대장!$I:$I<>""), ""))))}
A15: 이탈리아 | B15: 가야, 다르마지 | C15: 2015 | D15: 1번랙(천장) | E15: 1 | F15: 0 | G15: 1 | H15: 정상 | I15: {=IF(B15="", "", _xlfn.TEXTJOIN(", ", TRUE, _xlfn.UNIQUE(_xlfn._xlws.FILTER(입출고대장!$I:$I, (입출고대장!$D:$D=B15)*(입출고대장!$E:$E=C15)*(입출고대장!$F:$F=D15)*(입출고대장!$I:$I<>""), ""))))}
... A26: 미국 | B26: 로버트 몬다비,까베르네 소비뇽 리저브(50주년 에디션) | C26: 2013 | D26: 2번랙 | E26: 3 | F26: 0 | G26: 3 | H26: 정상 | I26: {=IF(B26="", "", _xlfn.TEXTJOIN(", ", TRUE, _xlfn.UNIQUE(_xlfn._xlws.FILTER(입출고대장!$I:$I, (입출고대장!$D:$D=B26)*(입출고대장!$E:$E=C26)*(입출고대장!$F:$F=D26)*(입출고대장!$I:$I<>""), ""))))} -> 50주년 에디션
A27: 미국 | B27: 로버트 몬다비,까베르네 소비뇽 버티칼 세트 | C27: NV | D27: 2번랙 | E27: 3 | F27: 0 | G27: 3 | H27: 정상 | I27: {=IF(B27="", "", _xlfn.TEXTJOIN(", ", TRUE, _xlfn.UNIQUE(_xlfn._xlws.FILTER(입출고대장!$I:$I, (입출고대장!$D:$D=B27)*(입출고대장!$E:$E=C27)*(입출고대장!$F:$F=D27)*(입출고대장!$I:$I<>""), ""))))} -> 세트상품
A28: 프랑스 | B28: 페블레, 꼬르똥 샤를마뉴 그랑 크뤼 | C28: 2010 | D28: 2번랙 | E28: 12 | F28: 0 | G28: 12 | H28: 정상 | I28: {=IF(B28="", "", _xlfn.TEXTJOIN(", ", TRUE, _xlfn.UNIQUE(_xlfn._xlws.FILTER(입출고대장!$I:$I, (입출고대장!$D:$D=B28)*(입출고대장!$E:$E=C28)*(입출고대장!$F:$F=D28)*(입출고대장!$I:$I<>""), ""))))}
A29: 프랑스 | B29: 페블레, 샹베르땡 끌로 드 베즈 우브레 로딘 그랑크뤼 | C29: 2018 | D29: 3번랙 | E29: 4 | F29: 0 | G29: 4 | H29: 정상 | I29: {=IF(B29="", "", _xlfn.TEXTJOIN(", ", TRUE, _xlfn.UNIQUE(_xlfn._xlws.FILTER(입출고대장!$I:$I, (입출고대장!$D:$D=B29)*(입출고대장!$E:$E=C29)*(입출고대장!$F:$F=D29)*(입출고대장!$I:$I<>""), ""))))}
A30: 프랑스 | B30: 페블레, 샹베르땡 끌로 드 베즈 우브레 로딘 그랑크뤼 | C30: 2019 | D30: 3번랙 | E30: 6 | F30: 0 | G30: 6 | H30: 정상 | I30: {=IF(B30="", "", _xlfn.TEXTJOIN(", ", TRUE, _xlfn.UNIQUE(_xlfn._xlws.FILTER(입출고대장!$I:$I, (입출고대장!$D:$D=B30)*(입출고대장!$E:$E=C30)*(입출고대장!$F:$F=D30)*(입출고대장!$I:$I<>""), ""))))}
A31: 프랑스 | B31: 페블레, 샹베르땡 끌로 드 베즈 우브레 로딘 그랑크뤼 | C31: 2020 | D31: 3번랙 | E31: 2 | F31: 0 | G31: 2 | H31: 정상 | I31: {=IF(B31="", "", _xlfn.TEXTJOIN(", ", TRUE, _xlfn.UNIQUE(_xlfn._xlws.FILTER(입출고대장!$I:$I, (입출고대장!$D:$D=B31)*(입출고대장!$E:$E=C31)*(입출고대장!$F:$F=D31)*(입출고대장!$I:$I<>""), ""))))}
A32: 프랑스 | B32: 페블레,바타르 몽라쉐 그랑 크뤼 | C32: 2010 | D32: 3번랙 | E32: 3 | F32: 0 | G32: 3 | H32: 정상 | I32: {=IF(B32="", "", _xlfn.TEXTJOIN(", ", TRUE, _xlfn.UNIQUE(_xlfn._xlws.FILTER(입출고대장!$I:$I, (입출고대장!$D:$D=B32)*(입출고대장!$E:$E=C32)*(입출고대장!$F:$F=D32)*(입출고대장!$I:$I<>""), ""))))}
A33: 프랑스 | B33: 페블레,바타르 몽라쉐 그랑 크뤼 | C33: 2021 | D33: 3번랙 | E33: 3 | F33: 0 | G33: 3 | H33: 정상 | I33: {=IF(B33="", "", _xlfn.TEXTJOIN(", ", TRUE, _xlfn.UNIQUE(_xlfn._xlws.FILTER(입출고대장!$I:$I, (입출고대장!$D:$D=B33)*(입출고대장!$E:$E=C33)*(입출고대장!$F:$F=D33)*(입출고대장!$I:$I<>""), ""))))}
A34: 프랑스 | B34: 페블레,비엥브뉘 바타르 몽라쉐 그랑 크뤼 | C34: 2011 | D34: 3번랙 | E34: 6 | F34: 0 | G34: 6 | H34: 정상 | I34: {=IF(B34="", "", _xlfn.TEXTJOIN(", ", TRUE, _xlfn.UNIQUE(_xlfn._xlws.FILTER(입출고대장!$I:$I, (입출고대장!$D:$D=B34)*(입출고대장!$E:$E=C34)*(입출고대장!$F:$F=D34)*(입출고대장!$I:$I<>""), ""))))} -> 검정 나무 케이스 6병
A35: 이탈리아 | B35: 루체 브루넬로 디 몬탈치노 1500ml | C35: 2009 | D35: 4번랙 | E35: 4 | F35: 0 | G35: 4 | H35: 정상 | I35: {=IF(B35="", "", _xlfn.TEXTJOIN(", ", TRUE, _xlfn.UNIQUE(_xlfn._xlws.FILTER(입출고대장!$I:$I, (입출고대장!$D:$D=B35)*(입출고대장!$E:$E=C35)*(입출고대장!$F:$F=D35)*(입출고대장!$I:$I<>""), ""))))} -> 매그넘
A36: 이탈리아 | B36: 루체 브루넬로 디 몬탈치노 1500ml | C36: 2012 | D36: 4번랙 | E36: 4 | F36: 0 | G36: 4 | H36: 정상 | I36: {=IF(B36="", "", _xlfn.TEXTJOIN(", ", TRUE, _xlfn.UNIQUE(_xlfn._xlws.FILTER(입출고대장!$I:$I, (입출고대장!$D:$D=B36)*(입출고대장!$E:$E=C36)*(입출고대장!$F:$F=D36)*(입출고대장!$I:$I<>""), ""))))} -> 매그넘
A37: 이탈리아 | B37: 루체 브루넬로 디 몬탈치노 3000ml | C37: 2012 | D37: 4번랙 | E37: 2 | F37: 0 | G37: 2 | H37: 정상 | I37: {=IF(B37="", "", _xlfn.TEXTJOIN(", ", TRUE, _xlfn.UNIQUE(_xlfn._xlws.FILTER(입출고대장!$I:$I, (입출고대장!$D:$D=B37)*(입출고대장!$E:$E=C37)*(입출고대장!$F:$F=D37)*(입출고대장!$I:$I<>""), ""))))} -> 더블매그넘
A38: 이탈리아 | B38: 프레스코발디,카스텔지오콘도 리제르바 1500ml | C38: 2008 | D38: 4번랙 | E38: 3 | F38: 0 | G38: 3 | H38: 정상 | I38: {=IF(B38="", "", _xlfn.TEXTJOIN(", ", TRUE, _xlfn.UNIQUE(_xlfn._xlws.FILTER(입출고대장!$I:$I, (입출고대장!$D:$D=B38)*(입출고대장!$E:$E=C38)*(입출고대장!$F:$F=D38)*(입출고대장!$I:$I<>""), ""))))} -> 매그넘
A39: 이탈리아 | B39: 프레스코발디,카스텔지오콘도 리제르바 1500ml | C39: 2010 | D39: 4번랙 | E39: 7 | F39: 0 | G39: 7 | H39: 정상 | I39: {=IF(B39="", "", _xlfn.TEXTJOIN(", ", TRUE, _xlfn.UNIQUE(_xlfn._xlws.FILTER(입출고대장!$I:$I, (입출고대장!$D:$D=B39)*(입출고대장!$E:$E=C39)*(입출고대장!$F:$F=D39)*(입출고대장!$I:$I<>""), ""))))} -> 매그넘
... A45: 이탈리아 | B45: 루체 | C45: 2011 | D45: 5번랙 | E45: 1 | F45: 0 | G45: 1 | H45: 정상 | I45: {=IF(B45="", "", _xlfn.TEXTJOIN(", ", TRUE, _xlfn.UNIQUE(_xlfn._xlws.FILTER(입출고대장!$I:$I, (입출고대장!$D:$D=B45)*(입출고대장!$E:$E=C45)*(입출고대장!$F:$F=D45)*(입출고대장!$I:$I<>""), ""))))} -> 선물용
A46: 칠레 | B46: 비네도 차드윅 | C46: NV | D46: 5번랙 | E46: 1 | F46: 0 | G46: 1 | H46: 정상 | I46: {=IF(B46="", "", _xlfn.TEXTJOIN(", ", TRUE, _xlfn.UNIQUE(_xlfn._xlws.FILTER(입출고대장!$I:$I, (입출고대장!$D:$D=B46)*(입출고대장!$E:$E=C46)*(입출고대장!$F:$F=D46)*(입출고대장!$I:$I<>""), ""))))} -> 선물용
A47: 프랑스 | B47: (OT)Domaine Coche-Dury Puligny Montrachet Les Enseigneres | C47: 2018 | D47: 5번랙 | E47: 1 | F47: 0 | G47: 1 | H47: 정상 | I47: {=IF(B47="", "", _xlfn.TEXTJOIN(", ", TRUE, _xlfn.UNIQUE(_xlfn._xlws.FILTER(입출고대장!$I:$I, (입출고대장!$D:$D=B47)*(입출고대장!$E:$E=C47)*(입출고대장!$F:$F=D47)*(입출고대장!$I:$I<>""), ""))))}
A48: 프랑스 | B48: (OT)Henri Boillot Chevalier Montrachet Grand Cru Blanc | C48: 2018 | D48: 5번랙 | E48: 1 | F48: 0 | G48: 1 | H48: 정상 | I48: {=IF(B48="", "", _xlfn.TEXTJOIN(", ", TRUE, _xlfn.UNIQUE(_xlfn._xlws.FILTER(입출고대장!$I:$I, (입출고대장!$D:$D=B48)*(입출고대장!$E:$E=C48)*(입출고대장!$F:$F=D48)*(입출고대장!$I:$I<>""), ""))))}
A49: 프랑스 | B49: Ch. Les Carmes Haut Brion | C49: 2022 | D49: 5번랙 | E49: 5 | F49: 0 | G49: 5 | H49: 정상 | I49: {=IF(B49="", "", _xlfn.TEXTJOIN(", ", TRUE, _xlfn.UNIQUE(_xlfn._xlws.FILTER(입출고대장!$I:$I, (입출고대장!$D:$D=B49)*(입출고대장!$E:$E=C49)*(입출고대장!$F:$F=D49)*(입출고대장!$I:$I<>""), ""))))}
A50: 프랑스 | B50: Phillip Pacalet Chambolle Musigny 1er Cru "Les Sentiers" | C50: 2021 | D50: 5번랙 | E50: 1 | F50: 0 | G50: 1 | H50: 정상 | I50: {=IF(B50="", "", _xlfn.TEXTJOIN(", ", TRUE, _xlfn.UNIQUE(_xlfn._xlws.FILTER(입출고대장!$I:$I, (입출고대장!$D:$D=B50)*(입출고대장!$E:$E=C50)*(입출고대장!$F:$F=D50)*(입출고대장!$I:$I<>""), ""))))}
A51: 프랑스 | B51: 샤또 린치 바쥐 | C51: 2005 | D51: 5번랙 | E51: 1 | F51: 0 | G51: 1 | H51: 정상 | I51: {=IF(B51="", "", _xlfn.TEXTJOIN(", ", TRUE, _xlfn.UNIQUE(_xlfn._xlws.FILTER(입출고대장!$I:$I, (입출고대장!$D:$D=B51)*(입출고대장!$E:$E=C51)*(입출고대장!$F:$F=D51)*(입출고대장!$I:$I<>""), ""))))} -> 선물용
A52: 프랑스 | B52: 아르망드 브리냑 로제 750ml | C52: NV | D52: 5번랙 | E52: 6 | F52: 0 | G52: 6 | H52: 정상 | I52: {=IF(B52="", "", _xlfn.TEXTJOIN(", ", TRUE, _xlfn.UNIQUE(_xlfn._xlws.FILTER(입출고대장!$I:$I, (입출고대장!$D:$D=B52)*(입출고대장!$E:$E=C52)*(입출고대장!$F:$F=D52)*(입출고대장!$I:$I<>""), ""))))} -> 샴페인
A53: 프랑스 | B53: 크룩 KRUG 샴페인 | C53: NV | D53: 5번랙 | E53: 6 | F53: 0 | G53: 6 | H53: 정상 | I53: {=IF(B53="", "", _xlfn.TEXTJOIN(", ", TRUE, _xlfn.UNIQUE(_xlfn._xlws.FILTER(입출고대장!$I:$I, (입출고대장!$D:$D=B53)*(입출고대장!$E:$E=C53)*(입출고대장!$F:$F=D53)*(입출고대장!$I:$I<>""), ""))))} -> 샴페인
A54: 프랑스 | B54: 헨리옷 HENRIOT 샴페인 | C54: 1996 | D54: 5번랙 | E54: 4 | F54: 0 | G54: 4 | H54: 정상 | I54: {=IF(B54="", "", _xlfn.TEXTJOIN(", ", TRUE, _xlfn.UNIQUE(_xlfn._xlws.FILTER(입출고대장!$I:$I, (입출고대장!$D:$D=B54)*(입출고대장!$E:$E=C54)*(입출고대장!$F:$F=D54)*(입출고대장!$I:$I<>""), ""))))} -> 샴페인
A55: 호주 | B55: 우드커터스 쉬라즈 | C55: NV | D55: 5번랙 | E55: 1 | F55: 0 | G55: 1 | H55: 정상 | I55: {=IF(B55="", "", _xlfn.TEXTJOIN(", ", TRUE, _xlfn.UNIQUE(_xlfn._xlws.FILTER(입출고대장!$I:$I, (입출고대장!$D:$D=B55)*(입출고대장!$E:$E=C55)*(입출고대장!$F:$F=D55)*(입출고대장!$I:$I<>""), ""))))} -> 선물용
...
